<robot
  name="PoppyErgoJr">
  <link
    name="base_link">
    <inertial>
      <origin
        xyz="-0.00273845833301658 0.00821639745724029 -0.0338977122062899"
        rpy="0 0 0" />
      <mass
        value="0.0802410895423482" />
      <inertia
        ixx="0.000114301948063037"
        ixy="-1.74777682977275E-06"
        ixz="7.80638590037738E-06"
        iyy="0.000177560979735186"
        iyz="6.80763560469811E-06"
        izz="7.51325469990317E-05" />
    </inertial>
    <visual>
      <origin
        xyz="0 0 0"
        rpy="0 0 0" />
      <geometry>
        <mesh
          filename="package://PoppyErgoJr/meshes/base_link.STL" />
      </geometry>
      <material
        name="">
        <color
          rgba="0.752941176470588 0.752941176470588 0.752941176470588 1" />
      </material>
    </visual>
    <collision>
      <origin
        xyz="0 0 0"
        rpy="0 0 0" />
      <geometry>
        <mesh
          filename="package://PoppyErgoJr/meshes/base_link.STL" />
      </geometry>
    </collision>
  </link>
  <link
    name="long_U">
    <inertial>
      <origin
        xyz="-0.00243058056226709 1.1450593743232E-07 0.0129312523306501"
        rpy="0 0 0" />
      <mass
        value="0.0042118228619085" />
      <inertia
        ixx="5.78707668456099E-07"
        ixy="9.44283869980321E-12"
        ixz="-1.13587476220175E-07"
        iyy="1.25420346852677E-06"
        iyz="4.64830147260204E-12"
        izz="9.27174545760678E-07" />
    </inertial>
    <visual>
      <origin
        xyz="0 0 0"
        rpy="0 0 0" />
      <geometry>
        <mesh
          filename="package://PoppyErgoJr/meshes/long_U.STL" />
      </geometry>
      <material
        name="">
        <color
          rgba="1 1 1 1" />
      </material>
    </visual>
    <collision>
      <origin
        xyz="0 0 0"
        rpy="0 0 0" />
      <geometry>
        <mesh
          filename="package://PoppyErgoJr/meshes/long_U.STL" />
      </geometry>
    </collision>
  </link>
  <joint
    name="m1"
    type="continuous">
    <origin
      xyz="0 0 0.0327993216120967"
      rpy="-6.12303176911189E-17 0 0" />
    <parent
      link="base_link" />
    <child
      link="long_U" />
    <axis
      xyz="0 0 -1" />
  </joint>
  <link
    name="section_1">
    <inertial>
      <origin
        xyz="-0.000168296047337677 0.0134412831426778 -3.36410188291073E-09"
        rpy="0 0 0" />
      <mass
        value="0.0201321844066143" />
      <inertia
        ixx="6.51960684491039E-06"
        ixy="-5.35361387413225E-07"
        ixz="-5.67167085958051E-13"
        iyy="2.3720668608647E-06"
        iyz="-1.07202402970223E-12"
        izz="7.46616268702641E-06" />
    </inertial>
    <visual>
      <origin
        xyz="0 0 0"
        rpy="0 0 0" />
      <geometry>
        <mesh
          filename="package://PoppyErgoJr/meshes/section_1.STL" />
      </geometry>
      <material
        name="">
        <color
          rgba="0.752941176470588 0.752941176470588 0.752941176470588 1" />
      </material>
    </visual>
    <collision>
      <origin
        xyz="0 0 0"
        rpy="0 0 0" />
      <geometry>
        <mesh
          filename="package://PoppyErgoJr/meshes/section_1.STL" />
      </geometry>
    </collision>
  </link>
  <joint
    name="m2"
    type="continuous">
    <origin
      xyz="0 0 0.0240006783879033"
      rpy="1.5707963267949 0 0" />
    <parent
      link="long_U" />
    <child
      link="section_1" />
    <axis
      xyz="-1 0 0" />
  </joint>
  <link
    name="section_2">
    <inertial>
      <origin
        xyz="0.000407772974186086 0.00840914919415671 -1.07672203212329E-09"
        rpy="0 0 0" />
      <mass
        value="0.0178217251516966" />
      <inertia
        ixx="2.5230448864375E-06"
        ixy="-6.63873566658365E-08"
        ixz="-2.02107689681802E-13"
        iyy="1.6417712841432E-06"
        iyz="3.46919508983611E-13"
        izz="2.86561030340007E-06" />
    </inertial>
    <visual>
      <origin
        xyz="0 0 0"
        rpy="0 0 0" />
      <geometry>
        <mesh
          filename="package://PoppyErgoJr/meshes/section_2.STL" />
      </geometry>
      <material
        name="">
        <color
          rgba="0.752941176470588 0.752941176470588 0.752941176470588 1" />
      </material>
    </visual>
    <collision>
      <origin
        xyz="0 0 0"
        rpy="0 0 0" />
      <geometry>
        <mesh
          filename="package://PoppyErgoJr/meshes/section_2.STL" />
      </geometry>
    </collision>
  </link>
  <joint
    name="m3"
    type="continuous">
    <origin
      xyz="0 0.054 0"
      rpy="0 0 0" />
    <parent
      link="section_1" />
    <child
      link="section_2" />
    <axis
      xyz="-1 0 0" />
  </joint>
  <link
    name="section_3">
    <inertial>
      <origin
        xyz="-0.000529269977744569 -0.0148172531686621 -0.012354599443708"
        rpy="0 0 0" />
      <mass
        value="0.0201321844066143" />
      <inertia
        ixx="5.58716321477778E-06"
        ixy="3.84615911019909E-09"
        ixz="3.80051502924433E-07"
        iyy="6.00831891375737E-06"
        iyz="9.5061083881804E-08"
        izz="2.36437426368361E-06" />
    </inertial>
    <visual>
      <origin
        xyz="0 0 0"
        rpy="0 0 0" />
      <geometry>
        <mesh
          filename="package://PoppyErgoJr/meshes/section_3.STL" />
      </geometry>
      <material
        name="">
        <color
          rgba="0.752941176470588 0.752941176470588 0.752941176470588 1" />
      </material>
    </visual>
    <collision>
      <origin
        xyz="0 0 0"
        rpy="0 0 0" />
      <geometry>
        <mesh
          filename="package://PoppyErgoJr/meshes/section_3.STL" />
      </geometry>
    </collision>
  </link>
  <joint
    name="m4"
    type="continuous">
    <origin
      xyz="0 0.0298217741221248 0"
      rpy="3.14159265358979 0 0" />
    <parent
      link="section_2" />
    <child
      link="section_3" />
    <axis
      xyz="0 1 0" />
  </joint>
  <link
    name="holder_section">
    <inertial>
      <origin
        xyz="0.00156167367585327 0.000187319118928692 0.0343475825698864"
        rpy="0 0 0" />
      <mass
        value="0.0387960284371531" />
      <inertia
        ixx="3.44286288318726E-05"
        ixy="-1.13486177538984E-08"
        ixz="2.63506574715545E-06"
        iyy="3.4700208349406E-05"
        iyz="1.77162718370014E-07"
        izz="4.19703129755245E-06" />
    </inertial>
    <visual>
      <origin
        xyz="0 0 0"
        rpy="0 0 0" />
      <geometry>
        <mesh
          filename="package://PoppyErgoJr/meshes/holder_section.STL" />
      </geometry>
      <material
        name="">
        <color
          rgba="0.752941176470588 0.752941176470588 0.752941176470588 1" />
      </material>
    </visual>
    <collision>
      <origin
        xyz="0 0 0"
        rpy="0 0 0" />
      <geometry>
        <mesh
          filename="package://PoppyErgoJr/meshes/holder_section.STL" />
      </geometry>
    </collision>
  </link>
  <joint
    name="m5"
    type="continuous">
    <origin
      xyz="0 -0.0151782258778752 -0.048"
      rpy="-3.14159265358979 0 0" />
    <parent
      link="section_3" />
    <child
      link="holder_section" />
    <axis
      xyz="-1 0 0" />
  </joint>
  <link
    name="holder">
    <inertial>
      <origin
        xyz="0.00890099509773648 0.0244006413452058 -0.00186616249502297"
        rpy="0 0 0" />
      <mass
        value="0.00493222432428107" />
      <inertia
        ixx="3.27799753440647E-06"
        ixy="6.99901573353274E-07"
        ixz="8.19280850680791E-08"
        iyy="8.98911120295044E-07"
        iyz="2.24813812159045E-07"
        izz="2.90909877106743E-06" />
    </inertial>
    <visual>
      <origin
        xyz="0 0 0"
        rpy="0 0 0" />
      <geometry>
        <mesh
          filename="package://PoppyErgoJr/meshes/holder.STL" />
      </geometry>
      <material
        name="">
        <color
          rgba="1 1 1 1" />
      </material>
    </visual>
    <collision>
      <origin
        xyz="0 0 0"
        rpy="0 0 0" />
      <geometry>
        <mesh
          filename="package://PoppyErgoJr/meshes/holder.STL" />
      </geometry>
    </collision>
  </link>
  <joint
    name="m6"
    type="continuous">
    <origin
      xyz="0 0 0.0579999999999998"
      rpy="1.5707963267949 3.4690027011428E-32 3.14159265358979" />
    <parent
      link="holder_section" />
    <child
      link="holder" />
    <axis
      xyz="0 0 -1" />
  </joint>
</robot>
